Workbook

Sheet Guide
B1: HR Workforce Analytics - Excel + Power BI Project
B2: What is this? | C2: Synthetic HR data for 3,000 employees analysed end-to-end in Excel, then handed to Power BI.
B3: Sheets | C3: Raw Data -> Clean Data -> Insights -> Dashboard. Review in that order.
B4: Raw Data | C4: As-collected file: duplicates, blank salary/department, gender typos, salary outliers, age typos.
B5: Clean Data | C5: Quality fixes applied; derived columns use live Excel formulas (IFS). Exported as Excel Table tCleanData for one-click Power BI import.
B6: Insights | C6: Pivot-style summaries built from SUMIFS / COUNTIFS / AVERAGEIFS + native Excel charts.
B7: Dashboard | C7: KPI cards, charts and findings for the HR manager.
B8: Power BI | C8: Power BI-ready star schema (DimEmployee, DimDate, FactEmploymentEvents, FactCompensation) sits in data/powerbi/. See powerbi/PowerBI_Build_Guide.md.
B10: Cleaning log | C10: 3010 raw rows scanned -> 3000 clean rows. What was fixed:
C11: * 10 duplicate employee rows removed
C12: * blank SalaryAnnual rows removed (unusable for compensation analytics)
C13: * blank Department rows removed
C14: * 'Unknown' + lower-case Gender values normalised; bad values removed
C15: * salary outliers (>$500k) excluded
C16: * Age typos (200+) excluded
C17: * derived columns AgeBand, SalaryBand, AttritionStatus added (live Excel formulas)
B19: Headline numbers
B20: Total employees | C20: 3000
B21: Active | C21: 2381
B22: Attrition rate | C22: 20.6%

Sheet Raw Data
A1: EmployeeID | B1: Gender | C1: Age | D1: MaritalStatus | E1: Education | F1: Department | G1: JobRole | H1: JobLevel | I1: OfficeLocation | J1: EmploymentType | K1: HireDate | L1: ExitDate | M1: IsActive | N1: ExitReason | O1: SalaryAnnual | P1: BonusPct | Q1: PerformanceRating | R1: SatisfactionScore | S1: TenureMonths | T1: AbsenteeDays | U1: Quality Flag
A2: E02861 | B2: Male | C2: 35 | D2: Married | E2: Master | F2: Finance | G2: Credit Analyst | H2: 2 | I2: Bengaluru | J2: Full-Time | K2: 44445 | L2: 44559 | M2: No | N2: Resigned | O2: 74500 | P2: 10 | Q2: 2 | R2: 6 | S2: 3 | T2: 9 | U2: OK
A3: E02721 | B3: Female | C3: 38 | D3: Single | E3: Bachelor | F3: IT | G3: Data Analyst | H3: 3 | I3: Mumbai | J3: Full-Time | K3: 44688 | L3: 44833 | M3: No | N3: Resigned | O3: 138000 | P3: 5 | Q3: 3 | R3: 8 | S3: 4 | T3: 0 | U3: OK
A4: E01877 | B4: Male | C4: 26 | D4: Married | E4: High School | F4: Finance | G4: Credit Analyst | H4: 1 | I4: Hyderabad | J4: Full-Time | K4: 44357 | M4: Yes | O4: 78000 | P4: 10 | Q4: 3 | R4: 9 | S4: 55 | T4: 3 | U4: OK
A5: E01954 | B5: Male | C5: 28 | D5: Married | E5: High School | F5: Human Resources | G5: Recruiter | H5: 3 | I5: Bengaluru | J5: Full-Time | K5: 45814 | M5: Yes | O5: 90000 | P5: 10 | Q5: 5 | R5: 5 | S5: 6 | T5: 5 | U5: OK
A6: E00129 | B6: Female | C6: 34 | D6: Married | E6: PhD | F6: Sales | G6: Business Development | H6: 1 | I6: Mumbai | J6: Full-Time | K6: 45352 | L6: 45411 | M6: No | N6: Layoff | O6: 73000 | P6: 0 | Q6: 4 | R6: 4 | S6: 1 | T6: 11 | U6: OK
A7: E00138 | B7: Male | C7: 32 | D7: Married | E7: Master | F7: Sales | G7: Sales Executive | H7: 3 | I7: Delhi | J7: Full-Time | K7: 44395 | M7: Yes | O7: 102500 | P7: 0 | Q7: 5 | R7: 1 | S7: 54 | T7: 13 | U7: OK
A8: E02149 | B8: male | C8: 30 | D8: Single | E8: Bachelor | F8: IT | G8: Software Engineer | H8: 3 | I8: Bengaluru | J8: Full-Time | K8: 44519 | M8: Yes | O8: 107000 | P8: 0 | Q8: 5 | R8: 6 | S8: 50 | T8: 9 | U8: OK
A9: E02093 | B9: Male | C9: 42 | D9: Married | E9: PhD | F9: Sales | G9: Account Executive | H9: 5 | I9: Mumbai | J9: Full-Time | K9: 44270 | M9: Yes | O9: 109000 | P9: 0 | Q9: 3 | R9: 2 | S9: 58 | T9: 11 | U9: OK
A10: E01810 | B10: Male | C10: 28 | D10: Married | E10: Diploma | F10: Finance | G10: Financial Analyst | H10: 3 | I10: Mumbai | J10: Full-Time | K10: 44964 | M10: Yes | O10: 85000 | P10: 0 | Q10: 3 | R10: 6 | S10: 35 | T10: 8 | U10: OK
A11: E02706 | B11: Female | C11: 42 | D11: Married | E11: PhD | F11: Operations | G11: Operations Analyst | H11: 6 | I11: Remote | J11: Full-Time | K11: 44190 | M11: Yes | O11: 122000 | P11: 15 | Q11: 3 | R11: 5 | S11: 61 | T11: 3 | U11: OK
A12: E02698 | B12: Female | C12: 27 | D12: Married | E12: Master | F12: IT | G12: IT Support | H12: 1 | I12: Delhi | J12: Full-Time | K12: 46001 | M12: Yes | O12: 108500 | P12: 0 | Q12: 4 | R12: 7 | S12: 1 | T12: 2 | U12: OK
A13: E01469 | B13: Male | C13: 31 | D13: Married | E13: Diploma | F13: Marketing | G13: Content Writer | H13: 3 | I13: Delhi | J13: Full-Time | K13: 44264 | M13: Yes | O13: 91000 | P13: 15 | Q13: 3 | R13: 3 | S13: 58 | T13: 8 | U13: OK
A14: E01727 | B14: Male | C14: 34 | D14: Married | E14: Diploma | F14: Human Resources | G14: HR Analyst | H14: 3 | I14: Bengaluru | J14: Full-Time | K14: 45876 | L14: 45928 | M14: No | N14: Retirement | O14: 83500 | P14: 0 | Q14: 5 | R14: 8 | S14: 1 | T14: 4 | U14: OK
A15: E00711 | B15: Male | C15: 34 | D15: Single | E15: PhD | F15: Operations | G15: Quality Analyst | H15: 2 | I15: Hyderabad | J15: Full-Time | K15: 45327 | M15: Yes | O15: 88000 | P15: 5 | Q15: 3 | R15: 4 | S15: 23 | T15: 0 | U15: OK
A16: E02942 | B16: Male | C16: 26 | D16: Single | E16: PhD | F16: Marketing | G16: Content Writer | H16: 1 | I16: Chennai | J16: Full-Time | K16: 43903 | M16: Yes | O16: 66000 | P16: 0 | Q16: 5 | R16: 4 | S16: 70 | T16: 5 | U16: OK
A17: E01887 | B17: Female | C17: 36 | D17: Divorced | E17: High School | F17: Research & Development | G17: Research Scientist | H17: 4 | I17: Remote | J17: Full-Time | K17: 44237 | M17: Yes | O17: 230500 | P17: 0 | Q17: 3 | R17: 8 | S17: 59 | T17: 17 | U17: OK
A18: E01441 | B18: Male | C18: 34 | D18: Single | E18: High School | F18: Marketing | G18: Content Writer | H18: 4 | I18: Remote | J18: Full-Time | K18: 45670 | L18: 45738 | M18: No | N18: Resigned | O18: 118500 | P18: 0 | Q18: 2 | R18: 2 | S18: 2 | T18: 2 | U18: OK
A19: E02533 | B19: Male | C19: 36 | D19: Married | E19: High School | F19: Finance | G19: Credit Analyst | H19: 6 | I19: Hyderabad | J19: Full-Time | K19: 45536 | M19: Yes | O19: 140000 | P19: 10 | Q19: 3 | R19: 6 | S19: 16 | T19: 1 | U19: OK
A20: E02649 | B20: Female | C20: 27 | D20: Married | E20: PhD | F20: Customer Support | G20: Escalation Specialist | H20: 2 | I20: Mumbai | J20: Full-Time | K20: 45837 | L20: 45943 | M20: No | N20: Retirement | O20: 50000 | P20: 0 | Q20: 2 | R20: 8 | S20: 3 | T20: 8 | U20: OK
A21: E00789 | B21: Male | C21: 28 | D21: Married | E21: Bachelor | F21: Customer Support | G21: Support Agent | H21: 1 | I21: Bengaluru | J21: Part-Time | K21: 44157 | M21: Yes | O21: 46000 | P21: 0 | Q21: 3 | R21: 6 | S21: 62 | T21: 0 | U21: OK
A22: E02693 | B22: Male | C22: 29 | D22: Single | E22: PhD | F22: Research & Development | G22: Research Scientist | H22: 4 | I22: Chennai | J22: Full-Time | K22: 44579 | M22: Yes | O22: 192500 | P22: 0 | Q22: 3 | R22: 8 | S22: 48 | T22: 4 | U22: OK
A23: E02594 | B23: Female | C23: 29 | D23: Married | E23: Master | F23: IT | G23: DevOps Engineer | H23: 2 | I23: Mumbai | J23: Full-Time | K23: 45970 | M23: Yes | O23: 148000 | P23: 10 | Q23: 4 | R23: 6 | S23: 1 | T23: 0 | U23: OK
A24: E00888 | B24: Female | C24: 26 | D24: Married | E24: PhD | F24: Customer Support | G24: Escalation Specialist | H24: 2 | I24: Bengaluru | J24: Part-Time | K24: 45589 | L24: 45644 | M24: No | N24: Resigned | O24: 61500 | P24: 5 | Q24: 5 | R24: 5 | S24: 1 | T24: 9 | U24: OK
A25: E00593 | B25: Female | C25: 32 | D25: Married | E25: PhD | F25: Finance | G25: Accountant | H25: 1 | I25: Bengaluru | J25: Full-Time | K25: 45452 | M25: Yes | O25: 81500 | P25: 15 | Q25: 4 | R25: 6 | S25: 19 | T25: 9 | U25: OK
A26: E01107 | B26: male | C26: 30 | D26: Married | E26: Diploma | F26: IT | G26: IT Support | H26: 1 | I26: Bengaluru | J26: Full-Time | K26: 45797 | M26: Yes | O26: 96500 | P26: 0 | Q26: 4 | R26: 8 | S26: 7 | T26: 8 | U26: OK
A27: E01361 | B27: male | C27: 30 | D27: Married | E27: Bachelor | F27: IT | G27: DevOps Engineer | H27: 1 | I27: Remote | J27: Full-Time | K27: 44960 | M27: Yes | O27: 92500 | P27: 10 | Q27: 4 | R27: 4 | S27: 35 | T27: 2 | U27: OK
A28: E02576 | B28: Male | C28: 45 | D28: Married | E28: PhD | F28: Customer Support | G28: Support Lead | H28: 7 | I28: Mumbai | J28: Full-Time | K28: 44969 | L28: 45107 | M28: No | N28: Resigned | O28: 108500 | P28: 0 | Q28: 5 | R28: 6 | S28: 4 | T28: 0 | U28: OK
A29: E00606 | B29: Male | C29: 36 | D29: Married | E29: Diploma | F29: IT | G29: Data Analyst | H29: 5 | I29: Delhi | J29: Full-Time | K29: 43924 | M29: Yes | O29: 180000 | P29: 10 | Q29: 4 | R29: 4 | S29: 69 | T29: 8 | U29: OK
A30: E00464 | B30: female | C30: 35 | D30: Married | E30: Bachelor | F30: Finance | G30: Financial Analyst | H30: 2 | I30: Hyderabad | J30: Full-Time | K30: 45723 | L30: 45820 | M30: No | N30: Layoff | O30: 95000 | P30: 20 | Q30: 5 | R30: 4 | S30: 3 | T30: 7 | U30: OK
A31: E01683 | B31: Female | C31: 24 | D31: Married | E31: High School | F31: Operations | G31: Quality Analyst | H31: 1 | I31: Delhi | J31: Full-Time | K31: 44895 | M31: Yes | O31: 73500 | P31: 10 | Q31: 4 | R31: 4 | S31: 37 | T31: 6 | U31: OK
A32: E00403 | B32: Male | C32: 27 | D32: Single | E32: Bachelor | F32: Customer Support | G32: Escalation Specialist | H32: 2 | I32: Chennai | J32: Full-Time | K32: 43832 | L32: 43921 | M32: No | N32: Resigned | O32: 81000 | P32: 5 | Q32: 3 | R32: 7 | S32: 2 | T32: 0 | U32: OK
A33: E01313 | B33: Female | C33: 28 | D33: Married | E33: High School | F33: Finance | G33: Credit Analyst | H33: 1 | I33: Bengaluru | J33: Full-Time | K33: 44040 | M33: Yes | O33: 91500 | P33: 0 | Q33: 4 | R33: 6 | S33: 66 | T33: 7 | U33: OK
A34: E02754 | B34: Female | C34: 35 | D34: Single | E34: Diploma | F34: IT | G34: Data Analyst | H34: 3 | I34: Hyderabad | J34: Part-Time | K34: 44775 | M34: Yes | O34: 177000 | P34: 0 | Q34: 5 | R34: 5 | S34: 41 | T34: 2 | U34: OK
A35: E02887 | B35: Male | C35: 28 | D35: Married | E35: High School | F35: Research & Development | G35: Product Engineer | H35: 3 | I35: Delhi | J35: Full-Time | K35: 44727 | M35: Yes | O35: 184500 | P35: 5 | Q35: 4 | R35: 5 | S35: 43 | T35: 6 | U35: OK
A36: E01898 | B36: Female | C36: 39 | D36: Single | E36: High School | F36: Operations | G36: Logistics Coordinator | H36: 4 | I36: Bengaluru | J36: Full-Time | K36: 45251 | M36: Yes | O36: 103500 | P36: 15 | Q36: 3 | R36: 5 | S36: 25 | T36: 9 | U36: OK
A37: E00058 | B37: male | C37: 26 | D37: Married | E37: PhD | F37: Finance | G37: Credit Analyst | H37: 1 | I37: Chennai | J37: Full-Time | K37: 45024 | M37: Yes | O37: 67500 | P37: 10 | Q37: 1 | R37: 6 | S37: 33 | T37: 4 | U37: OK
A38: E01466 | B38: Female | C38: 28 | D38: Married | E38: High School | F38: Marketing | G38: Marketing Analyst | H38: 1 | I38: Remote | J38: Full-Time | K38: 45741 | M38: Yes | O38: 83500 | P38: 0 | Q38: 4 | R38: 5 | S38: 9 | T38: 0 | U38: OK
A39: E02415 | B39: Female | C39: 32 | D39: Divorced | E39: Diploma | F39: Sales | G39: Business Development | H39: 2 | I39: Hyderabad | J39: Full-Time | K39: 45155 | L39: 45260 | M39: No | N39: Retirement | O39: 122500 | P39: 5 | Q39: 4 | R39: 6 | S39: 3 | T39: 8 | U39: OK
A40: E00167 | B40: Male | C40: 37 | D40: Single | E40: High School | F40: Marketing | G40: SEO Specialist | H40: 4 | I40: Hyderabad | J40: Contract | K40: 45253 | L40: 45395 | M40: No | N40: Resigned | O40: 127000 | P40: 5 | Q40: 3 | R40: 7 | S40: 4 | T40: 12 | U40: OK
...

Sheet Clean Data
A1: EmployeeID | B1: Gender | C1: Age | D1: MaritalStatus | E1: Education | F1: Department | G1: JobRole | H1: JobLevel | I1: OfficeLocation | J1: EmploymentType | K1: HireDate | L1: ExitDate | M1: IsActive | N1: ExitReason | O1: SalaryAnnual | P1: BonusPct | Q1: PerformanceRating | R1: SatisfactionScore | S1: TenureMonths | T1: AbsenteeDays | U1: AgeBand | V1: SalaryBand | W1: AttritionStatus
A2: E00001 | B2: Female | C2: 40 | D2: Single | E2: PhD | F2: IT | G2: Software Engineer | H2: 5 | I2: Delhi | J2: Full-Time | K2: 44318 | M2: Yes | O2: 212000 | P2: 5 | Q2: 4 | R2: 4 | S2: 56 | T2: 9 | U2: =IFS(C2<30,"Under 30",C2<40,"30-39",C2<50,"40-49",TRUE,"50+") | V2: =IFS(O2<60000,"Low (<60k)",O2<100000,"Mid (60-100k)",TRUE,"High (100k+)") | W2: =IF(M2="No","Attrited","Active")
A3: E00002 | B3: Female | C3: 35 | D3: Divorced | E3: PhD | F3: IT | G3: Software Engineer | H3: 2 | I3: Remote | J3: Full-Time | K3: 44284 | M3: Yes | O3: 170000 | P3: 0 | Q3: 4 | R3: 5 | S3: 57 | T3: 11 | U3: =IFS(C3<30,"Under 30",C3<40,"30-39",C3<50,"40-49",TRUE,"50+") | V3: =IFS(O3<60000,"Low (<60k)",O3<100000,"Mid (60-100k)",TRUE,"High (100k+)") | W3: =IF(M3="No","Attrited","Active")
A4: E00003 | B4: Female | C4: 31 | D4: Married | E4: Master | F4: Sales | G4: Sales Executive | H4: 3 | I4: Delhi | J4: Full-Time | K4: 44143 | M4: Yes | O4: 96000 | P4: 10 | Q4: 3 | R4: 8 | S4: 62 | T4: 12 | U4: =IFS(C4<30,"Under 30",C4<40,"30-39",C4<50,"40-49",TRUE,"50+") | V4: =IFS(O4<60000,"Low (<60k)",O4<100000,"Mid (60-100k)",TRUE,"High (100k+)") | W4: =IF(M4="No","Attrited","Active")
A5: E00004 | B5: Female | C5: 28 | D5: Married | E5: Master | F5: Customer Support | G5: Escalation Specialist | H5: 3 | I5: Chennai | J5: Full-Time | K5: 45464 | M5: Yes | O5: 70000 | P5: 5 | Q5: 3 | R5: 7 | S5: 18 | T5: 0 | U5: =IFS(C5<30,"Under 30",C5<40,"30-39",C5<50,"40-49",TRUE,"50+") | V5: =IFS(O5<60000,"Low (<60k)",O5<100000,"Mid (60-100k)",TRUE,"High (100k+)") | W5: =IF(M5="No","Attrited","Active")
A6: E00005 | B6: Male | C6: 27 | D6: Married | E6: Diploma | F6: Customer Support | G6: Escalation Specialist | H6: 2 | I6: Delhi | J6: Full-Time | K6: 45952 | M6: Yes | O6: 74000 | P6: 5 | Q6: 5 | R6: 8 | S6: 2 | T6: 4 | U6: =IFS(C6<30,"Under 30",C6<40,"30-39",C6<50,"40-49",TRUE,"50+") | V6: =IFS(O6<60000,"Low (<60k)",O6<100000,"Mid (60-100k)",TRUE,"High (100k+)") | W6: =IF(M6="No","Attrited","Active")
A7: E00006 | B7: Female | C7: 41 | D7: Married | E7: Bachelor | F7: Sales | G7: Business Development | H7: 6 | I7: Bengaluru | J7: Full-Time | K7: 45702 | M7: Yes | O7: 156500 | P7: 10 | Q7: 3 | R7: 1 | S7: 10 | T7: 18 | U7: =IFS(C7<30,"Under 30",C7<40,"30-39",C7<50,"40-49",TRUE,"50+") | V7: =IFS(O7<60000,"Low (<60k)",O7<100000,"Mid (60-100k)",TRUE,"High (100k+)") | W7: =IF(M7="No","Attrited","Active")
A8: E00007 | B8: Female | C8: 38 | D8: Married | E8: PhD | F8: Finance | G8: Credit Analyst | H8: 5 | I8: Remote | J8: Full-Time | K8: 43868 | M8: Yes | O8: 158000 | P8: 5 | Q8: 5 | R8: 8 | S8: 71 | T8: 3 | U8: =IFS(C8<30,"Under 30",C8<40,"30-39",C8<50,"40-49",TRUE,"50+") | V8: =IFS(O8<60000,"Low (<60k)",O8<100000,"Mid (60-100k)",TRUE,"High (100k+)") | W8: =IF(M8="No","Attrited","Active")
A9: E00008 | B9: Female | C9: 26 | D9: Married | E9: Master | F9: Customer Support | G9: Support Lead | H9: 2 | I9: Delhi | J9: Full-Time | K9: 43968 | L9: 44098 | M9: No | N9: Resigned | O9: 82000 | P9: 0 | Q9: 3 | R9: 5 | S9: 4 | T9: 0 | U9: =IFS(C9<30,"Under 30",C9<40,"30-39",C9<50,"40-49",TRUE,"50+") | V9: =IFS(O9<60000,"Low (<60k)",O9<100000,"Mid (60-100k)",TRUE,"High (100k+)") | W9: =IF(M9="No","Attrited","Active")
A10: E00009 | B10: Male | C10: 34 | D10: Married | E10: Diploma | F10: Customer Support | G10: Support Lead | H10: 1 | I10: Mumbai | J10: Full-Time | K10: 44922 | L10: 44967 | M10: No | N10: Resigned | O10: 56000 | P10: 5 | Q10: 5 | R10: 8 | S10: 1 | T10: 16 | U10: =IFS(C10<30,"Under 30",C10<40,"30-39",C10<50,"40-49",TRUE,"50+") | V10: =IFS(O10<60000,"Low (<60k)",O10<100000,"Mid (60-100k)",TRUE,"High (100k+)") | W10: =IF(M10="No","Attrited","Active")
A11: E00010 | B11: Female | C11: 45 | D11: Married | E11: Diploma | F11: Sales | G11: Business Development | H11: 7 | I11: Chennai | J11: Full-Time | K11: 44325 | M11: Yes | O11: 163500 | P11: 15 | Q11: 4 | R11: 6 | S11: 56 | T11: 6 | U11: =IFS(C11<30,"Under 30",C11<40,"30-39",C11<50,"40-49",TRUE,"50+") | V11: =IFS(O11<60000,"Low (<60k)",O11<100000,"Mid (60-100k)",TRUE,"High (100k+)") | W11: =IF(M11="No","Attrited","Active")
A12: E00011 | B12: Female | C12: 46 | D12: Married | E12: Master | F12: Operations | G12: Operations Analyst | H12: 7 | I12: Mumbai | J12: Full-Time | K12: 44744 | M12: Yes | O12: 168000 | P12: 15 | Q12: 4 | R12: 8 | S12: 42 | T12: 10 | U12: =IFS(C12<30,"Under 30",C12<40,"30-39",C12<50,"40-49",TRUE,"50+") | V12: =IFS(O12<60000,"Low (<60k)",O12<100000,"Mid (60-100k)",TRUE,"High (100k+)") | W12: =IF(M12="No","Attrited","Active")
A13: E00012 | B13: Male | C13: 24 | D13: Married | E13: Bachelor | F13: Customer Support | G13: Support Lead | H13: 1 | I13: Remote | J13: Contract | K13: 45961 | M13: Yes | O13: 71500 | P13: 15 | Q13: 3 | R13: 9 | S13: 2 | T13: 11 | U13: =IFS(C13<30,"Under 30",C13<40,"30-39",C13<50,"40-49",TRUE,"50+") | V13: =IFS(O13<60000,"Low (<60k)",O13<100000,"Mid (60-100k)",TRUE,"High (100k+)") | W13: =IF(M13="No","Attrited","Active")
A14: E00013 | B14: Male | C14: 34 | D14: Married | E14: High School | F14: Operations | G14: Operations Analyst | H14: 3 | I14: Chennai | J14: Contract | K14: 45074 | M14: Yes | O14: 95500 | P14: 0 | Q14: 4 | R14: 6 | S14: 31 | T14: 2 | U14: =IFS(C14<30,"Under 30",C14<40,"30-39",C14<50,"40-49",TRUE,"50+") | V14: =IFS(O14<60000,"Low (<60k)",O14<100000,"Mid (60-100k)",TRUE,"High (100k+)") | W14: =IF(M14="No","Attrited","Active")
A15: E00014 | B15: Male | C15: 33 | D15: Single | E15: PhD | F15: Finance | G15: Credit Analyst | H15: 6 | I15: Mumbai | J15: Full-Time | K15: 45465 | M15: Yes | O15: 168000 | P15: 5 | Q15: 4 | R15: 7 | S15: 18 | T15: 5 | U15: =IFS(C15<30,"Under 30",C15<40,"30-39",C15<50,"40-49",TRUE,"50+") | V15: =IFS(O15<60000,"Low (<60k)",O15<100000,"Mid (60-100k)",TRUE,"High (100k+)") | W15: =IF(M15="No","Attrited","Active")
A16: E00015 | B16: Female | C16: 25 | D16: Married | E16: Master | F16: Customer Support | G16: Support Agent | H16: 1 | I16: Bengaluru | J16: Part-Time | K16: 45948 | L16: 46021 | M16: No | N16: Resigned | O16: 51000 | P16: 0 | Q16: 3 | R16: 4 | S16: 2 | T16: 8 | U16: =IFS(C16<30,"Under 30",C16<40,"30-39",C16<50,"40-49",TRUE,"50+") | V16: =IFS(O16<60000,"Low (<60k)",O16<100000,"Mid (60-100k)",TRUE,"High (100k+)") | W16: =IF(M16="No","Attrited","Active")
A17: E00016 | B17: Male | C17: 28 | D17: Married | E17: Bachelor | F17: Human Resources | G17: HR Analyst | H17: 3 | I17: Hyderabad | J17: Full-Time | K17: 45746 | L17: 45856 | M17: No | N17: Resigned | O17: 83000 | P17: 0 | Q17: 4 | R17: 5 | S17: 3 | T17: 5 | U17: =IFS(C17<30,"Under 30",C17<40,"30-39",C17<50,"40-49",TRUE,"50+") | V17: =IFS(O17<60000,"Low (<60k)",O17<100000,"Mid (60-100k)",TRUE,"High (100k+)") | W17: =IF(M17="No","Attrited","Active")
A18: E00017 | B18: Male | C18: 36 | D18: Married | E18: PhD | F18: Research & Development | G18: Data Scientist | H18: 5 | I18: Bengaluru | J18: Full-Time | K18: 44578 | M18: Yes | O18: 228500 | P18: 5 | Q18: 4 | R18: 4 | S18: 48 | T18: 2 | U18: =IFS(C18<30,"Under 30",C18<40,"30-39",C18<50,"40-49",TRUE,"50+") | V18: =IFS(O18<60000,"Low (<60k)",O18<100000,"Mid (60-100k)",TRUE,"High (100k+)") | W18: =IF(M18="No","Attrited","Active")
A19: E00018 | B19: Female | C19: 29 | D19: Married | E19: High School | F19: Finance | G19: Accountant | H19: 1 | I19: Bengaluru | J19: Full-Time | K19: 44374 | M19: Yes | O19: 73500 | P19: 5 | Q19: 3 | R19: 5 | S19: 54 | T19: 0 | U19: =IFS(C19<30,"Under 30",C19<40,"30-39",C19<50,"40-49",TRUE,"50+") | V19: =IFS(O19<60000,"Low (<60k)",O19<100000,"Mid (60-100k)",TRUE,"High (100k+)") | W19: =IF(M19="No","Attrited","Active")
A20: E00019 | B20: Female | C20: 29 | D20: Single | E20: PhD | F20: Human Resources | G20: Recruiter | H20: 1 | I20: Chennai | J20: Part-Time | K20: 45119 | M20: Yes | O20: 57000 | P20: 0 | Q20: 5 | R20: 7 | S20: 30 | T20: 3 | U20: =IFS(C20<30,"Under 30",C20<40,"30-39",C20<50,"40-49",TRUE,"50+") | V20: =IFS(O20<60000,"Low (<60k)",O20<100000,"Mid (60-100k)",TRUE,"High (100k+)") | W20: =IF(M20="No","Attrited","Active")
A21: E00020 | B21: Male | C21: 37 | D21: Married | E21: PhD | F21: IT | G21: IT Support | H21: 3 | I21: Remote | J21: Full-Time | K21: 45265 | M21: Yes | O21: 157000 | P21: 5 | Q21: 4 | R21: 8 | S21: 25 | T21: 7 | U21: =IFS(C21<30,"Under 30",C21<40,"30-39",C21<50,"40-49",TRUE,"50+") | V21: =IFS(O21<60000,"Low (<60k)",O21<100000,"Mid (60-100k)",TRUE,"High (100k+)") | W21: =IF(M21="No","Attrited","Active")
A22: E00021 | B22: Male | C22: 34 | D22: Married | E22: Master | F22: Operations | G22: Logistics Coordinator | H22: 1 | I22: Bengaluru | J22: Full-Time | K22: 44861 | M22: Yes | O22: 96500 | P22: 10 | Q22: 3 | R22: 9 | S22: 38 | T22: 7 | U22: =IFS(C22<30,"Under 30",C22<40,"30-39",C22<50,"40-49",TRUE,"50+") | V22: =IFS(O22<60000,"Low (<60k)",O22<100000,"Mid (60-100k)",TRUE,"High (100k+)") | W22: =IF(M22="No","Attrited","Active")
A23: E00022 | B23: Female | C23: 23 | D23: Single | E23: PhD | F23: Marketing | G23: Content Writer | H23: 1 | I23: Mumbai | J23: Full-Time | K23: 43914 | L23: 44038 | M23: No | N23: Layoff | O23: 55000 | P23: 0 | Q23: 4 | R23: 8 | S23: 4 | T23: 11 | U23: =IFS(C23<30,"Under 30",C23<40,"30-39",C23<50,"40-49",TRUE,"50+") | V23: =IFS(O23<60000,"Low (<60k)",O23<100000,"Mid (60-100k)",TRUE,"High (100k+)") | W23: =IF(M23="No","Attrited","Active")
A24: E00023 | B24: Female | C24: 31 | D24: Married | E24: Diploma | F24: Operations | G24: Logistics Coordinator | H24: 2 | I24: Mumbai | J24: Full-Time | K24: 45289 | L24: 45347 | M24: No | N24: Performance / Termination | O24: 99000 | P24: 5 | Q24: 4 | R24: 6 | S24: 1 | T24: 2 | U24: =IFS(C24<30,"Under 30",C24<40,"30-39",C24<50,"40-49",TRUE,"50+") | V24: =IFS(O24<60000,"Low (<60k)",O24<100000,"Mid (60-100k)",TRUE,"High (100k+)") | W24: =IF(M24="No","Attrited","Active")
A25: E00024 | B25: Female | C25: 31 | D25: Married | E25: PhD | F25: Finance | G25: Credit Analyst | H25: 3 | I25: Remote | J25: Full-Time | K25: 43926 | M25: Yes | O25: 94500 | P25: 0 | Q25: 5 | R25: 8 | S25: 69 | T25: 12 | U25: =IFS(C25<30,"Under 30",C25<40,"30-39",C25<50,"40-49",TRUE,"50+") | V25: =IFS(O25<60000,"Low (<60k)",O25<100000,"Mid (60-100k)",TRUE,"High (100k+)") | W25: =IF(M25="No","Attrited","Active")
A26: E00025 | B26: Female | C26: 30 | D26: Married | E26: Bachelor | F26: Finance | G26: Financial Analyst | H26: 3 | I26: Mumbai | J26: Full-Time | K26: 45131 | M26: Yes | O26: 144000 | P26: 15 | Q26: 4 | R26: 9 | S26: 29 | T26: 4 | U26: =IFS(C26<30,"Under 30",C26<40,"30-39",C26<50,"40-49",TRUE,"50+") | V26: =IFS(O26<60000,"Low (<60k)",O26<100000,"Mid (60-100k)",TRUE,"High (100k+)") | W26: =IF(M26="No","Attrited","Active")
A27: E00026 | B27: Female | C27: 32 | D27: Single | E27: High School | F27: Operations | G27: Operations Analyst | H27: 2 | I27: Bengaluru | J27: Full-Time | K27: 44960 | M27: Yes | O27: 92000 | P27: 0 | Q27: 4 | R27: 4 | S27: 35 | T27: 3 | U27: =IFS(C27<30,"Under 30",C27<40,"30-39",C27<50,"40-49",TRUE,"50+") | V27: =IFS(O27<60000,"Low (<60k)",O27<100000,"Mid (60-100k)",TRUE,"High (100k+)") | W27: =IF(M27="No","Attrited","Active")
A28: E00027 | B28: Male | C28: 28 | D28: Married | E28: PhD | F28: Sales | G28: Sales Executive | H28: 3 | I28: Bengaluru | J28: Full-Time | K28: 45974 | M28: Yes | O28: 83000 | P28: 15 | Q28: 3 | R28: 5 | S28: 1 | T28: 4 | U28: =IFS(C28<30,"Under 30",C28<40,"30-39",C28<50,"40-49",TRUE,"50+") | V28: =IFS(O28<60000,"Low (<60k)",O28<100000,"Mid (60-100k)",TRUE,"High (100k+)") | W28: =IF(M28="No","Attrited","Active")
A29: E00028 | B29: Female | C29: 35 | D29: Married | E29: PhD | F29: Research & Development | G29: Data Scientist | H29: 3 | I29: Remote | J29: Full-Time | K29: 44013 | M29: Yes | O29: 131500 | P29: 0 | Q29: 5 | R29: 4 | S29: 66 | T29: 0 | U29: =IFS(C29<30,"Under 30",C29<40,"30-39",C29<50,"40-49",TRUE,"50+") | V29: =IFS(O29<60000,"Low (<60k)",O29<100000,"Mid (60-100k)",TRUE,"High (100k+)") | W29: =IF(M29="No","Attrited","Active")
A30: E00029 | B30: Female | C30: 29 | D30: Divorced | E30: Bachelor | F30: Human Resources | G30: Recruiter | H30: 2 | I30: Chennai | J30: Full-Time | K30: 44608 | M30: Yes | O30: 63000 | P30: 5 | Q30: 3 | R30: 7 | S30: 47 | T30: 5 | U30: =IFS(C30<30,"Under 30",C30<40,"30-39",C30<50,"40-49",TRUE,"50+") | V30: =IFS(O30<60000,"Low (<60k)",O30<100000,"Mid (60-100k)",TRUE,"High (100k+)") | W30: =IF(M30="No","Attrited","Active")
A31: E00030 | B31: Female | C31: 31 | D31: Single | E31: Bachelor | F31: Sales | G31: Sales Executive | H31: 1 | I31: Mumbai | J31: Full-Time | K31: 44530 | M31: Yes | O31: 92500 | P31: 10 | Q31: 3 | R31: 7 | S31: 49 | T31: 6 | U31: =IFS(C31<30,"Under 30",C31<40,"30-39",C31<50,"40-49",TRUE,"50+") | V31: =IFS(O31<60000,"Low (<60k)",O31<100000,"Mid (60-100k)",TRUE,"High (100k+)") | W31: =IF(M31="No","Attrited","Active")
A32: E00031 | B32: Male | C32: 26 | D32: Married | E32: Master | F32: Human Resources | G32: HR Analyst | H32: 2 | I32: Delhi | J32: Full-Time | K32: 46010 | M32: Yes | O32: 82000 | P32: 5 | Q32: 5 | R32: 2 | S32: 1 | T32: 7 | U32: =IFS(C32<30,"Under 30",C32<40,"30-39",C32<50,"40-49",TRUE,"50+") | V32: =IFS(O32<60000,"Low (<60k)",O32<100000,"Mid (60-100k)",TRUE,"High (100k+)") | W32: =IF(M32="No","Attrited","Active")
A33: E00032 | B33: Female | C33: 36 | D33: Married | E33: Diploma | F33: IT | G33: DevOps Engineer | H33: 4 | I33: Mumbai | J33: Full-Time | K33: 45956 | M33: Yes | O33: 195500 | P33: 10 | Q33: 5 | R33: 6 | S33: 2 | T33: 7 | U33: =IFS(C33<30,"Under 30",C33<40,"30-39",C33<50,"40-49",TRUE,"50+") | V33: =IFS(O33<60000,"Low (<60k)",O33<100000,"Mid (60-100k)",TRUE,"High (100k+)") | W33: =IF(M33="No","Attrited","Active")
A34: E00033 | B34: Female | C34: 36 | D34: Married | E34: Bachelor | F34: Operations | G34: Quality Analyst | H34: 2 | I34: Hyderabad | J34: Full-Time | K34: 45162 | L34: 45288 | M34: No | N34: Retirement | O34: 86000 | P34: 15 | Q34: 4 | R34: 4 | S34: 4 | T34: 6 | U34: =IFS(C34<30,"Under 30",C34<40,"30-39",C34<50,"40-49",TRUE,"50+") | V34: =IFS(O34<60000,"Low (<60k)",O34<100000,"Mid (60-100k)",TRUE,"High (100k+)") | W34: =IF(M34="No","Attrited","Active")
A35: E00034 | B35: Female | C35: 39 | D35: Single | E35: Bachelor | F35: IT | G35: IT Support | H35: 4 | I35: Mumbai | J35: Full-Time | K35: 45394 | M35: Yes | O35: 144000 | P35: 15 | Q35: 4 | R35: 5 | S35: 20 | T35: 8 | U35: =IFS(C35<30,"Under 30",C35<40,"30-39",C35<50,"40-49",TRUE,"50+") | V35: =IFS(O35<60000,"Low (<60k)",O35<100000,"Mid (60-100k)",TRUE,"High (100k+)") | W35: =IF(M35="No","Attrited","Active")
A36: E00035 | B36: Female | C36: 33 | D36: Single | E36: Master | F36: Research & Development | G36: Product Engineer | H36: 4 | I36: Remote | J36: Full-Time | K36: 45189 | L36: 45257 | M36: No | N36: Relocation | O36: 207500 | P36: 10 | Q36: 3 | R36: 4 | S36: 2 | T36: 7 | U36: =IFS(C36<30,"Under 30",C36<40,"30-39",C36<50,"40-49",TRUE,"50+") | V36: =IFS(O36<60000,"Low (<60k)",O36<100000,"Mid (60-100k)",TRUE,"High (100k+)") | W36: =IF(M36="No","Attrited","Active")
A37: E00036 | B37: Female | C37: 27 | D37: Married | E37: Master | F37: IT | G37: DevOps Engineer | H37: 3 | I37: Hyderabad | J37: Full-Time | K37: 45947 | M37: Yes | O37: 128000 | P37: 0 | Q37: 5 | R37: 6 | S37: 2 | T37: 5 | U37: =IFS(C37<30,"Under 30",C37<40,"30-39",C37<50,"40-49",TRUE,"50+") | V37: =IFS(O37<60000,"Low (<60k)",O37<100000,"Mid (60-100k)",TRUE,"High (100k+)") | W37: =IF(M37="No","Attrited","Active")
A38: E00037 | B38: Female | C38: 37 | D38: Single | E38: Diploma | F38: Executive | G38: CEO | H38: 3 | I38: Chennai | J38: Full-Time | K38: 45218 | M38: Yes | O38: 258500 | P38: 0 | Q38: 5 | R38: 6 | S38: 26 | T38: 7 | U38: =IFS(C38<30,"Under 30",C38<40,"30-39",C38<50,"40-49",TRUE,"50+") | V38: =IFS(O38<60000,"Low (<60k)",O38<100000,"Mid (60-100k)",TRUE,"High (100k+)") | W38: =IF(M38="No","Attrited","Active")
A39: E00038 | B39: Male | C39: 28 | D39: Single | E39: Bachelor | F39: Research & Development | G39: Research Scientist | H39: 2 | I39: Hyderabad | J39: Full-Time | K39: 43877 | M39: Yes | O39: 112000 | P39: 5 | Q39: 5 | R39: 7 | S39: 71 | T39: 14 | U39: =IFS(C39<30,"Under 30",C39<40,"30-39",C39<50,"40-49",TRUE,"50+") | V39: =IFS(O39<60000,"Low (<60k)",O39<100000,"Mid (60-100k)",TRUE,"High (100k+)") | W39: =IF(M39="No","Attrited","Active")
A40: E00039 | B40: Female | C40: 30 | D40: Married | E40: Bachelor | F40: Human Resources | G40: HR Analyst | H40: 3 | I40: Bengaluru | J40: Part-Time | K40: 44013 | M40: Yes | O40: 90500 | P40: 5 | Q40: 5 | R40: 8 | S40: 66 | T40: 1 | U40: =IFS(C40<30,"Under 30",C40<40,"30-39",C40<50,"40-49",TRUE,"50+") | V40: =IFS(O40<60000,"Low (<60k)",O40<100000,"Mid (60-100k)",TRUE,"High (100k+)") | W40: =IF(M40="No","Attrited","Active")
...

Sheet Insights
A1: 1) Headcount and attrition rate by department
A2: Department | B2: Headcount | C2: Avg Salary | D2: Attrited | E2: Attrition Rate
A3: Executive | B3: =COUNTIF('Clean Data'!$F$2:$F$3001,A3) | C3: =IF(B3=0,0,ROUND(AVERAGEIFS('Clean Data'!$O$2:$O$3001,'Clean Data'!$F$2:$F$3001,A3),0)) | D3: =COUNTIFS('Clean Data'!$F$2:$F$3001,A3,'Clean Data'!$M$2:$M$3001,"No") | E3: =IF(B3=0,0,D3/B3)
A4: Finance | B4: =COUNTIF('Clean Data'!$F$2:$F$3001,A4) | C4: =IF(B4=0,0,ROUND(AVERAGEIFS('Clean Data'!$O$2:$O$3001,'Clean Data'!$F$2:$F$3001,A4),0)) | D4: =COUNTIFS('Clean Data'!$F$2:$F$3001,A4,'Clean Data'!$M$2:$M$3001,"No") | E4: =IF(B4=0,0,D4/B4)
A5: Human Resources | B5: =COUNTIF('Clean Data'!$F$2:$F$3001,A5) | C5: =IF(B5=0,0,ROUND(AVERAGEIFS('Clean Data'!$O$2:$O$3001,'Clean Data'!$F$2:$F$3001,A5),0)) | D5: =COUNTIFS('Clean Data'!$F$2:$F$3001,A5,'Clean Data'!$M$2:$M$3001,"No") | E5: =IF(B5=0,0,D5/B5)
A6: IT | B6: =COUNTIF('Clean Data'!$F$2:$F$3001,A6) | C6: =IF(B6=0,0,ROUND(AVERAGEIFS('Clean Data'!$O$2:$O$3001,'Clean Data'!$F$2:$F$3001,A6),0)) | D6: =COUNTIFS('Clean Data'!$F$2:$F$3001,A6,'Clean Data'!$M$2:$M$3001,"No") | E6: =IF(B6=0,0,D6/B6)
A7: Operations | B7: =COUNTIF('Clean Data'!$F$2:$F$3001,A7) | C7: =IF(B7=0,0,ROUND(AVERAGEIFS('Clean Data'!$O$2:$O$3001,'Clean Data'!$F$2:$F$3001,A7),0)) | D7: =COUNTIFS('Clean Data'!$F$2:$F$3001,A7,'Clean Data'!$M$2:$M$3001,"No") | E7: =IF(B7=0,0,D7/B7)
A8: Marketing | B8: =COUNTIF('Clean Data'!$F$2:$F$3001,A8) | C8: =IF(B8=0,0,ROUND(AVERAGEIFS('Clean Data'!$O$2:$O$3001,'Clean Data'!$F$2:$F$3001,A8),0)) | D8: =COUNTIFS('Clean Data'!$F$2:$F$3001,A8,'Clean Data'!$M$2:$M$3001,"No") | E8: =IF(B8=0,0,D8/B8)
A9: Sales | B9: =COUNTIF('Clean Data'!$F$2:$F$3001,A9) | C9: =IF(B9=0,0,ROUND(AVERAGEIFS('Clean Data'!$O$2:$O$3001,'Clean Data'!$F$2:$F$3001,A9),0)) | D9: =COUNTIFS('Clean Data'!$F$2:$F$3001,A9,'Clean Data'!$M$2:$M$3001,"No") | E9: =IF(B9=0,0,D9/B9)
A10: Customer Support | B10: =COUNTIF('Clean Data'!$F$2:$F$3001,A10) | C10: =IF(B10=0,0,ROUND(AVERAGEIFS('Clean Data'!$O$2:$O$3001,'Clean Data'!$F$2:$F$3001,A10),0)) | D10: =COUNTIFS('Clean Data'!$F$2:$F$3001,A10,'Clean Data'!$M$2:$M$3001,"No") | E10: =IF(B10=0,0,D10/B10)
A11: Research & Development | B11: =COUNTIF('Clean Data'!$F$2:$F$3001,A11) | C11: =IF(B11=0,0,ROUND(AVERAGEIFS('Clean Data'!$O$2:$O$3001,'Clean Data'!$F$2:$F$3001,A11),0)) | D11: =COUNTIFS('Clean Data'!$F$2:$F$3001,A11,'Clean Data'!$M$2:$M$3001,"No") | E11: =IF(B11=0,0,D11/B11)
A12: Total | B12: =SUM(B3:B11) | C12: =ROUND(AVERAGE('Clean Data'!$O$2:$O$3001),0) | D12: =SUM(D3:D11) | E12: =IF(B12=0,0,D12/B12)
A14: 2) Average salary by gender and job level (pay-gap snapshot)
A15: Job Level | B15: Female | C15: Male | D15: Pay Gap (M vs F)
A16: Level 1 | B16: =ROUND(AVERAGEIFS('Clean Data'!$O$2:$O$3001,'Clean Data'!$H$2:$H$3001,"Level 1",'Clean Data'!$B$2:$B$3001,"Female"),0) | C16: =ROUND(AVERAGEIFS('Clean Data'!$O$2:$O$3001,'Clean Data'!$H$2:$H$3001,"Level 1",'Clean Data'!$B$2:$B$3001,"Male"),0) | D16: =IF(B16=0,0,(C16-B16)/B16)
A17: Level 2 | B17: =ROUND(AVERAGEIFS('Clean Data'!$O$2:$O$3001,'Clean Data'!$H$2:$H$3001,"Level 2",'Clean Data'!$B$2:$B$3001,"Female"),0) | C17: =ROUND(AVERAGEIFS('Clean Data'!$O$2:$O$3001,'Clean Data'!$H$2:$H$3001,"Level 2",'Clean Data'!$B$2:$B$3001,"Male"),0) | D17: =IF(B17=0,0,(C17-B17)/B17)
A18: Level 3 | B18: =ROUND(AVERAGEIFS('Clean Data'!$O$2:$O$3001,'Clean Data'!$H$2:$H$3001,"Level 3",'Clean Data'!$B$2:$B$3001,"Female"),0) | C18: =ROUND(AVERAGEIFS('Clean Data'!$O$2:$O$3001,'Clean Data'!$H$2:$H$3001,"Level 3",'Clean Data'!$B$2:$B$3001,"Male"),0) | D18: =IF(B18=0,0,(C18-B18)/B18)
A19: Level 4 | B19: =ROUND(AVERAGEIFS('Clean Data'!$O$2:$O$3001,'Clean Data'!$H$2:$H$3001,"Level 4",'Clean Data'!$B$2:$B$3001,"Female"),0) | C19: =ROUND(AVERAGEIFS('Clean Data'!$O$2:$O$3001,'Clean Data'!$H$2:$H$3001,"Level 4",'Clean Data'!$B$2:$B$3001,"Male"),0) | D19: =IF(B19=0,0,(C19-B19)/B19)
A20: Level 5 | B20: =ROUND(AVERAGEIFS('Clean Data'!$O$2:$O$3001,'Clean Data'!$H$2:$H$3001,"Level 5",'Clean Data'!$B$2:$B$3001,"Female"),0) | C20: =ROUND(AVERAGEIFS('Clean Data'!$O$2:$O$3001,'Clean Data'!$H$2:$H$3001,"Level 5",'Clean Data'!$B$2:$B$3001,"Male"),0) | D20: =IF(B20=0,0,(C20-B20)/B20)
A21: Level 6 | B21: =ROUND(AVERAGEIFS('Clean Data'!$O$2:$O$3001,'Clean Data'!$H$2:$H$3001,"Level 6",'Clean Data'!$B$2:$B$3001,"Female"),0) | C21: =ROUND(AVERAGEIFS('Clean Data'!$O$2:$O$3001,'Clean Data'!$H$2:$H$3001,"Level 6",'Clean Data'!$B$2:$B$3001,"Male"),0) | D21: =IF(B21=0,0,(C21-B21)/B21)
A22: Level 7 | B22: =ROUND(AVERAGEIFS('Clean Data'!$O$2:$O$3001,'Clean Data'!$H$2:$H$3001,"Level 7",'Clean Data'!$B$2:$B$3001,"Female"),0) | C22: =ROUND(AVERAGEIFS('Clean Data'!$O$2:$O$3001,'Clean Data'!$H$2:$H$3001,"Level 7",'Clean Data'!$B$2:$B$3001,"Male"),0) | D22: =IF(B22=0,0,(C22-B22)/B22)
A25: 3) Hiring trend by year
A26: Year | B26: Hires
A27: 2020 | B27: =COUNTIFS('Clean Data'!$K$2:$K$3001,">="&DATE(2020,1,1),'Clean Data'!$K$2:$K$3001,"<="&DATE(2020,12,31))
A28: 2021 | B28: =COUNTIFS('Clean Data'!$K$2:$K$3001,">="&DATE(2021,1,1),'Clean Data'!$K$2:$K$3001,"<="&DATE(2021,12,31))
A29: 2022 | B29: =COUNTIFS('Clean Data'!$K$2:$K$3001,">="&DATE(2022,1,1),'Clean Data'!$K$2:$K$3001,"<="&DATE(2022,12,31))
A30: 2023 | B30: =COUNTIFS('Clean Data'!$K$2:$K$3001,">="&DATE(2023,1,1),'Clean Data'!$K$2:$K$3001,"<="&DATE(2023,12,31))
A31: 2024 | B31: =COUNTIFS('Clean Data'!$K$2:$K$3001,">="&DATE(2024,1,1),'Clean Data'!$K$2:$K$3001,"<="&DATE(2024,12,31))
A32: 2025 | B32: =COUNTIFS('Clean Data'!$K$2:$K$3001,">="&DATE(2025,1,1),'Clean Data'!$K$2:$K$3001,"<="&DATE(2025,12,31))
A36: 4) Departures by exit reason
A37: Exit Reason | B37: Count
A38: Resigned | B38: =COUNTIF('Clean Data'!$N$2:$N$3001,A38)
A39: Retirement | B39: =COUNTIF('Clean Data'!$N$2:$N$3001,A39)
A40: Performance / Termination | B40: =COUNTIF('Clean Data'!$N$2:$N$3001,A40)
A41: Layoff | B41: =COUNTIF('Clean Data'!$N$2:$N$3001,A41)
A42: Relocation | B42: =COUNTIF('Clean Data'!$N$2:$N$3001,A42)

Sheet Dashboard
A1: HR WORKFORCE DASHBOARD
A2: Snapshot: 31-Dec-2025 | Synthetic HR data | Built in Excel, Power BI-ready
A4: TOTAL HEADCOUNT | C4: ACTIVE EMPLOYEES | E4: ATTRITION RATE | G4: AVG SALARY (USD) | I4: AVG TENURE (MONTHS) | K4: AVG SATISFACTION (/10)
A5: =COUNTA('Clean Data'!$A$2:$A$3001) | C5: =COUNTIF('Clean Data'!$M$2:$M$3001,"Yes") | E5: =1-COUNTIF('Clean Data'!$M$2:$M$3001,"Yes")/COUNTA('Clean Data'!$A$2:$A$3001) | G5: =ROUND(AVERAGE('Clean Data'!$O$2:$O$3001),0) | I5: =ROUND(AVERAGE('Clean Data'!$S$2:$S$3001),1) | K5: =ROUND(AVERAGE('Clean Data'!$R$2:$R$3001),1)
A8: Workforce snapshots (live formulas, see Insights)
A22: KEY FINDINGS & RECOMMENDATIONS
A23: * Headcount 3000 (active 2381, attrition 20.6%).
A24: * Attrition skews to Sales, Customer Support and Operations - review comp and workload there.
A25: * Exits concentrate in short tenures (<18 months) and junior levels - strengthen onboarding.
A26: * Run the pay-gap table (Insights sheet) each quarter; flag any level where gap > 10%.
A27: * Use exit-reason trend (Insights) to target retention: e.g. offer flexibility to reduce 'Relocation'.
